2022-03-09 18:58:30 WARNING (SyncWorker_1) [homeassistant.loader] We found a custom integration googlewifi which has not been tested by Home Assistant. This component might cause stability problems, be sure to disable it if you experience issues with Home Assistant
2022-03-09 18:58:30 WARNING (SyncWorker_0) [homeassistant.loader] We found a custom integration sonoff which has not been tested by Home Assistant. This component might cause stability problems, be sure to disable it if you experience issues with Home Assistant
2022-03-09 18:58:30 WARNING (SyncWorker_2) [homeassistant.loader] We found a custom integration fullykiosk which has not been tested by Home Assistant. This component might cause stability problems, be sure to disable it if you experience issues with Home Assistant
2022-03-09 18:58:30 WARNING (SyncWorker_5) [homeassistant.loader] We found a custom integration ui_lovelace_minimalist which has not been tested by Home Assistant. This component might cause stability problems, be sure to disable it if you experience issues with Home Assistant
2022-03-09 18:58:30 WARNING (SyncWorker_3) [homeassistant.loader] We found a custom integration govee_ble_hci which has not been tested by Home Assistant. This component might cause stability problems, be sure to disable it if you experience issues with Home Assistant
2022-03-09 18:58:30 WARNING (SyncWorker_0) [homeassistant.loader] We found a custom integration hacs which has not been tested by Home Assistant. This component might cause stability problems, be sure to disable it if you experience issues with Home Assistant
2022-03-09 18:58:30 WARNING (SyncWorker_2) [homeassistant.loader] We found a custom integration vesync_formatbce which has not been tested by Home Assistant. This component might cause stability problems, be sure to disable it if you experience issues with Home Assistant
2022-03-09 18:58:30 WARNING (SyncWorker_4) [homeassistant.loader] We found a custom integration wyzeapi which has not been tested by Home Assistant. This component might cause stability problems, be sure to disable it if you experience issues with Home Assistant
2022-03-09 18:58:32 WARNING (Recorder) [homeassistant.components.recorder.util] The system could not validate that the sqlite3 database at //config/home-assistant_v2.db was shutdown cleanly
2022-03-09 18:58:32 WARNING (Recorder) [homeassistant.components.recorder.util] Ended unfinished session (id=15 from 2022-03-07 05:13:53.586540)
2022-03-09 18:58:39 ERROR (MainThread) [homeassistant.setup] Setup failed for resources: Integration not found.
2022-03-09 18:58:47 WARNING (MainThread) [homeassistant.components.vesync.fan] fuckmist - Unknown device type - Classic300S
2022-03-09 18:58:52 ERROR (MainThread) [homeassistant.components.light] Platform tplink does not generate unique IDs. ID 84D81B0FA600 already exists - ignoring light.porch_light
2022-03-09 18:58:52 ERROR (MainThread) [homeassistant.components.sensor] Platform tplink does not generate unique IDs. ID 84:d8:1b:0f:a6:00_current_power_w already exists - ignoring sensor.porch_light_current_consumption
2022-03-09 18:58:52 ERROR (MainThread) [homeassistant.components.sensor] Platform tplink does not generate unique IDs. ID 84:d8:1b:0f:a6:00_total_energy_kwh already exists - ignoring sensor.porch_light_total_consumption
2022-03-09 18:58:52 ERROR (MainThread) [homeassistant.components.sensor] Platform tplink does not generate unique IDs. ID 84:d8:1b:0f:a6:00_today_energy_kwh already exists - ignoring sensor.porch_light_today_s_consumption
2022-03-09 18:59:47 ERROR (MainThread) [custom_components.googlewifi] Unexpected error fetching GoogleWifi data: 'operationState'
Traceback (most recent call last):
  File "/usr/src/homeassistant/homeassistant/helpers/update_coordinator.py", line 187, in _async_refresh
    self.data = await self._async_update_data()
  File "/config/custom_components/googlewifi/__init__.py", line 227, in _async_update_data
    speedtest_result = await self.api.run_speed_test(
  File "/usr/local/lib/python3.9/site-packages/googlewifi/__init__.py", line 569, in run_speed_test
    status = status["operationState"]
KeyError: 'operationState'
2022-03-09 19:00:25 ERROR (MainThread) [custom_components.googlewifi] Unexpected error fetching GoogleWifi data: 'operationState'
Traceback (most recent call last):
  File "/usr/src/homeassistant/homeassistant/helpers/update_coordinator.py", line 187, in _async_refresh
    self.data = await self._async_update_data()
  File "/config/custom_components/googlewifi/__init__.py", line 227, in _async_update_data
    speedtest_result = await self.api.run_speed_test(
  File "/usr/local/lib/python3.9/site-packages/googlewifi/__init__.py", line 569, in run_speed_test
    status = status["operationState"]
KeyError: 'operationState'
2022-03-09 19:16:05 ERROR (MainThread) [frontend.js.latest.202203010] http://homeassistant:8123/frontend_latest/0fab353e.js:2:307 TypeError: can't convert undefined to object
2022-03-09 19:33:11 ERROR (MainThread) [custom_components.googlewifi] Unexpected error fetching GoogleWifi data: 'operationState'
Traceback (most recent call last):
  File "/usr/src/homeassistant/homeassistant/helpers/update_coordinator.py", line 187, in _async_refresh
    self.data = await self._async_update_data()
  File "/config/custom_components/googlewifi/__init__.py", line 171, in _async_update_data
    system_data = await self.api.get_systems()
  File "/usr/local/lib/python3.9/site-packages/googlewifi/__init__.py", line 191, in get_systems
    return await self.structure_systems(response)
  File "/usr/local/lib/python3.9/site-packages/googlewifi/__init__.py", line 284, in structure_systems
    sensitive_info = await self.get_sensitive_info(system_id=this_system["id"], station_ids=station_ids)
  File "/usr/local/lib/python3.9/site-packages/googlewifi/__init__.py", line 617, in get_sensitive_info
    status = status["operationState"]
KeyError: 'operationState'
2022-03-09 20:06:39 ERROR (MainThread) [homeassistant.components.tplink.coordinator] Error fetching 192.168.86.59 data: Unable to connect to the device: 192.168.86.59
2022-03-09 20:06:39 ERROR (MainThread) [homeassistant.components.tplink.coordinator] Error fetching 192.168.86.58 data: Unable to connect to the device: 192.168.86.58
2022-03-09 20:13:20 ERROR (MainThread) [custom_components.googlewifi] Unexpected error fetching GoogleWifi data: 'operationState'
Traceback (most recent call last):
  File "/usr/src/homeassistant/homeassistant/helpers/update_coordinator.py", line 187, in _async_refresh
    self.data = await self._async_update_data()
  File "/config/custom_components/googlewifi/__init__.py", line 171, in _async_update_data
    system_data = await self.api.get_systems()
  File "/usr/local/lib/python3.9/site-packages/googlewifi/__init__.py", line 191, in get_systems
    return await self.structure_systems(response)
  File "/usr/local/lib/python3.9/site-packages/googlewifi/__init__.py", line 284, in structure_systems
    sensitive_info = await self.get_sensitive_info(system_id=this_system["id"], station_ids=station_ids)
  File "/usr/local/lib/python3.9/site-packages/googlewifi/__init__.py", line 617, in get_sensitive_info
    status = status["operationState"]
KeyError: 'operationState'
2022-03-09 20:27:48 ERROR (MainThread) [homeassistant.components.hassio.handler] Client error on /homeassistant/restart request Server disconnected
